{
  "cve": {
    "data_type": "CVE",
    "data_format": "MITRE",
    "data_version": "4.0",
    "CVE_data_meta": {
      "ID": "CVE-2019-16729",
      "ASSIGNER": "cve@mitre.org"
    },
    "affects": {
      "vendor": {
        "vendor_data": [

        ]
      }
    },
    "problemtype": {
      "problemtype_data": [
        {
          "description": [

          ]
        }
      ]
    },
    "references": {
      "reference_data": [
        {
          "url": "https://bugzilla.suse.com/show_bug.cgi?id=1150510#c1",
          "name": "https://bugzilla.suse.com/show_bug.cgi?id=1150510#c1",
          "refsource": "MISC",
          "tags": [

          ]
        },
        {
          "url": "https://sourceforge.net/p/pam-python/code/ci/0247ab687b4347cc52859ca461fb0126dd7e2ebe/",
          "name": "https://sourceforge.net/p/pam-python/code/ci/0247ab687b4347cc52859ca461fb0126dd7e2ebe/",
          "refsource": "MISC",
          "tags": [

          ]
        },
        {
          "url": "https://tracker.debian.org/news/1066790/accepted-pam-python-107-1-source-amd64-all-into-unstable/",
          "name": "https://tracker.debian.org/news/1066790/accepted-pam-python-107-1-source-amd64-all-into-unstable/",
          "refsource": "MISC",
          "tags": [

          ]
        }
      ]
    },
    "description": {
      "description_data": [
        {
          "lang": "en",
          "value": "pam-python before 1.0.7-1 has an issue in regard to the default environment variable handling of Python, which could allow for local root escalation in certain PAM setups."
        }
      ]
    }
  },
  "configurations": {
    "CVE_data_version": "4.0",
    "nodes": [

    ]
  },
  "impact": {
  },
  "publishedDate": "2019-09-24T05:15Z",
  "lastModifiedDate": "2019-09-24T11:59Z"
}