{
  "cve": {
    "data_type": "CVE",
    "data_format": "MITRE",
    "data_version": "4.0",
    "CVE_data_meta": {
      "ID": "CVE-2018-16855",
      "ASSIGNER": "cve@mitre.org"
    },
    "affects": {
      "vendor": {
        "vendor_data": [

        ]
      }
    },
    "problemtype": {
      "problemtype_data": [
        {
          "description": [

          ]
        }
      ]
    },
    "references": {
      "reference_data": [
        {
          "url": "https://bugzilla.redhat.com/show_bug.cgi?id=CVE-2018-16855",
          "name": "https://bugzilla.redhat.com/show_bug.cgi?id=CVE-2018-16855",
          "refsource": "CONFIRM",
          "tags": [

          ]
        },
        {
          "url": "https://docs.powerdns.com/recursor/security-advisories/powerdns-advisory-2018-09.html",
          "name": "https://docs.powerdns.com/recursor/security-advisories/powerdns-advisory-2018-09.html",
          "refsource": "MISC",
          "tags": [

          ]
        }
      ]
    },
    "description": {
      "description_data": [
        {
          "lang": "en",
          "value": "An issue has been found in PowerDNS Recursor before version 4.1.8 where a remote attacker sending a DNS query can trigger an out-of-bounds memory read while computing the hash of the query for a packet cache lookup, possibly leading to a crash."
        }
      ]
    }
  },
  "configurations": {
    "CVE_data_version": "4.0",
    "nodes": [

    ]
  },
  "impact": {
  },
  "publishedDate": "2018-12-03T14:29Z",
  "lastModifiedDate": "2018-12-03T14:29Z"
}