{
  "cve": {
    "data_type": "CVE",
    "data_format": "MITRE",
    "data_version": "4.0",
    "CVE_data_meta": {
      "ID": "CVE-2019-9948",
      "ASSIGNER": "cve@mitre.org"
    },
    "affects": {
      "vendor": {
        "vendor_data": [

        ]
      }
    },
    "problemtype": {
      "problemtype_data": [
        {
          "description": [

          ]
        }
      ]
    },
    "references": {
      "reference_data": [
        {
          "url": "http://www.securityfocus.com/bid/107549",
          "name": "107549",
          "refsource": "BID",
          "tags": [

          ]
        },
        {
          "url": "https://bugs.python.org/issue35907",
          "name": "https://bugs.python.org/issue35907",
          "refsource": "MISC",
          "tags": [

          ]
        },
        {
          "url": "https://github.com/python/cpython/pull/11842",
          "name": "https://github.com/python/cpython/pull/11842",
          "refsource": "MISC",
          "tags": [

          ]
        }
      ]
    },
    "description": {
      "description_data": [
        {
          "lang": "en",
          "value": "urllib in Python 2.x through 2.7.16 supports the local_file: scheme, which makes it easier for remote attackers to bypass protection mechanisms that blacklist file: URIs, as demonstrated by triggering a urllib.urlopen('local_file:///etc/passwd') call."
        }
      ]
    }
  },
  "configurations": {
    "CVE_data_version": "4.0",
    "nodes": [

    ]
  },
  "impact": {
  },
  "publishedDate": "2019-03-23T18:29Z",
  "lastModifiedDate": "2019-03-25T13:29Z"
}