{
  "cve": {
    "data_type": "CVE",
    "data_format": "MITRE",
    "data_version": "4.0",
    "CVE_data_meta": {
      "ID": "CVE-2019-12902",
      "ASSIGNER": "cve@mitre.org"
    },
    "affects": {
      "vendor": {
        "vendor_data": [

        ]
      }
    },
    "problemtype": {
      "problemtype_data": [
        {
          "description": [

          ]
        }
      ]
    },
    "references": {
      "reference_data": [
        {
          "url": "https://pydio.com/en/community/releases/pydio-cells/pydio-cells-150-performances-features-security",
          "name": "https://pydio.com/en/community/releases/pydio-cells/pydio-cells-150-performances-features-security",
          "refsource": "MISC",
          "tags": [

          ]
        },
        {
          "url": "https://research.loginsoft.com/vulnerability/multiple-vulnerabilities-in-pydio-cells-1-4-1/",
          "name": "https://research.loginsoft.com/vulnerability/multiple-vulnerabilities-in-pydio-cells-1-4-1/",
          "refsource": "MISC",
          "tags": [

          ]
        }
      ]
    },
    "description": {
      "description_data": [
        {
          "lang": "en",
          "value": "Pydio Cells before 1.5.0 does incomplete cleanup of a user's data upon deletion. This allows a new user, holding the same User ID as a deleted user, to restore the deleted user's data."
        }
      ]
    }
  },
  "configurations": {
    "CVE_data_version": "4.0",
    "nodes": [

    ]
  },
  "impact": {
  },
  "publishedDate": "2019-06-20T00:15Z",
  "lastModifiedDate": "2019-06-20T11:34Z"
}